<?xml version="1.0"?>
<robot name="physics">

<material name="blue">
    <color rgba="0 0 0.8 1"/>
  </material>
  <material name="black">
    <color rgba="0 0 0 1"/>
  </material>
  <material name="white">
    <color rgba="1 1 1 1"/>
  </material>

  <!--body-->

  <link name="body">
    <visual>
      <origin rpy="0.0 0 0" xyz="0 0 0"/>
      <geometry>
        <mesh filename="package://spot/meshes/body.dae"/>
      </geometry>
      <material name="blue"/>
    </visual>
    <collision>
      <geometry>
        <mesh filename="package://spot/meshes/body.dae"/>
      </geometry>
      <origin rpy="0.0 0 0" xyz="0 0 0"/>
    </collision>
    <inertial>
      <mass value="1.0"/>
      <inertia ixx="1.0" ixy="0.0" ixz="0.0" iyy="1.0" iyz="0.0" izz="1.0"/>
    </inertial>
  </link>

  <!--left front shoulder-->

  <link name="left_front_joint">
    <visual>
      <origin rpy="0.0 0 0" xyz="0 0 0"/>
      <geometry>
        <mesh filename="package://spot/meshes/left_arm_joint.dae"/>
      </geometry>
      <material name="black"/>
    </visual>
    <collision>
      <geometry>
        <mesh filename="package://spot/meshes/left_arm_joint.dae"/>
      </geometry>
      <origin rpy="0.0 0 0" xyz="0 0 0"/>
    </collision>
    <inertial>
      <mass value="0.2"/>
      <inertia ixx="1.0" ixy="0.0" ixz="0.0" iyy="1.0" iyz="0.0" izz="1.0"/>
    </inertial>
  </link>


  <joint name="left_front_shoulder" type="revolute">
    <axis xyz="1 0 0"/>
    <limit effort="1000.0" lower="-0.436332" upper="0.436332" velocity="0.5"/>
    <origin rpy="0 0 0" xyz="0.78779 0.3786 0"/>
    <parent link="body"/>
    <child link="left_front_joint"/>
  </joint>

  <!--right front shoulder-->


  <link name="right_front_joint">
    <visual>
      <origin rpy="0.0 0 0" xyz="0 0 0"/>
      <geometry>
        <mesh filename="package://spot/meshes/right_arm_joint.dae"/>
      </geometry>
      <material name="black"/>
    </visual>
    <collision>
      <geometry>
        <mesh filename="package://spot/meshes/right_arm_joint.dae"/>
      </geometry>
      <origin rpy="0.0 0 0" xyz="0 0 0"/>
    </collision>
    <inertial>
      <mass value="0.2"/>
      <inertia ixx="1.0" ixy="0.0" ixz="0.0" iyy="1.0" iyz="0.0" izz="1.0"/>
    </inertial>
  </link>

  <joint name="right_front_shoulder" type="revolute">
    <axis xyz="1 0 0"/>
    <limit effort="1000.0" lower="-0.436332" upper="0.436332" velocity="0.5"/>
    <origin rpy="0 0 0" xyz="0.78779 -0.3786 0"/>
    <parent link="body"/>
    <child link="right_front_joint"/>
  </joint>

  <!--left back shoulder-->

  <link name="left_back_joint">
    <visual>
      <origin rpy="0.0 0 0" xyz="0 0 0"/>
      <geometry>
        <mesh filename="package://spot/meshes/left_arm_joint.dae"/>
      </geometry>
      <material name="black"/>
    </visual>
    <collision>
      <geometry>
        <mesh filename="package://spot/meshes/left_arm_joint.dae"/>
      </geometry>
      <origin rpy="0.0 0 0" xyz="0 0 0"/>
    </collision>
    <inertial>
      <mass value="0.2"/>
      <inertia ixx="1.0" ixy="0.0" ixz="0.0" iyy="1.0" iyz="0.0" izz="1.0"/>
    </inertial>
  </link>

  <joint name="left_back_shoulder" type="revolute">
    <axis xyz="1 0 0"/>
    <limit effort="1000.0" lower="-0.436332" upper="0.436332" velocity="0.5"/>
    <origin rpy="0 0 0" xyz="-1.0696 0.3786 0"/>
    <parent link="body"/>
    <child link="left_back_joint"/>
  </joint>

  <!--right back shoulder-->

  <link name="right_back_joint">
    <visual>
      <origin rpy="0.0 0 0" xyz="0 0 0"/>
      <geometry>
        <mesh filename="package://spot/meshes/right_arm_joint.dae"/>
      </geometry>
      <material name="black"/>
    </visual>
    <collision>
      <geometry>
        <mesh filename="package://spot/meshes/right_arm_joint.dae"/>
      </geometry>
      <origin rpy="0.0 0 0" xyz="0 0 0"/>
    </collision>
    <inertial>
      <mass value="0.2"/>
      <inertia ixx="1.0" ixy="0.0" ixz="0.0" iyy="1.0" iyz="0.0" izz="1.0"/>
    </inertial>
  </link>

  <joint name="right_back_shoulder" type="revolute">
    <axis xyz="1 0 0"/>
    <limit effort="1000.0" lower="-0.436332" upper="0.436332" velocity="0.5"/>
    <origin rpy="0 0 0" xyz="-1.0696 -0.3786 0"/>
    <parent link="body"/>
    <child link="right_back_joint"/>
  </joint>

  <!--left front arm-->

  <link name="left_front_arm">
    <visual>
      <origin rpy="0.0 0 0" xyz="0 0.2 -0.57"/>
      <geometry>
        <mesh filename="package://spot/meshes/left_arm.dae"/>
      </geometry>
      <material name="blue"/>
    </visual>
    <collision>
      <geometry>
        <mesh filename="package://spot/meshes/left_arm.dae"/>
      </geometry>
      <origin rpy="0.0 0 0" xyz="0 0.2 -0.57"/>
    </collision>
    <inertial>
      <mass value="0.7"/>
      <inertia ixx="1.0" ixy="0.0" ixz="0.0" iyy="1.0" iyz="0.0" izz="1.0"/>
    </inertial>
  </link>


  <joint name="left_front_arm_to_shoulder" type="revolute">
    <axis xyz="0 1 0"/>
    <limit effort="1000.0" lower="-0.610865" upper="1.48353" velocity="0.5"/>
    <origin rpy="0 0.610865 0" xyz="0 0.2594 0.107"/>
    <parent link="left_front_joint"/>
    <child link="left_front_arm"/>
  </joint>

  <!--left back arm-->

  <link name="left_back_arm">
    <visual>
      <origin rpy="0.0 0 0" xyz="0 0.2 -0.57"/>
      <geometry>
        <mesh filename="package://spot/meshes/left_arm.dae"/>
      </geometry>
      <material name="blue"/>
    </visual>
    <collision>
      <geometry>
        <mesh filename="package://spot/meshes/left_arm.dae"/>
      </geometry>
      <origin rpy="0.0 0 0" xyz="0 0.2 -0.57"/>
    </collision>
    <inertial>
      <mass value="0.7"/>
      <inertia ixx="1.0" ixy="0.0" ixz="0.0" iyy="1.0" iyz="0.0" izz="1.0"/>
    </inertial>
  </link>


  <joint name="left_back_arm_to_shoulder" type="revolute">
    <axis xyz="0 1 0"/>
    <limit effort="1000.0" lower="-0.610865" upper="1.48353" velocity="0.5"/>
    <origin rpy="0 0.610865 0" xyz="0 0.2594 0.107"/>
    <parent link="left_back_joint"/>
    <child link="left_back_arm"/>
  </joint>

  <!--right front arm-->

  <link name="right_front_arm">
    <visual>
      <origin rpy="0.0 0 0" xyz="0 -0.2 -0.57"/>
      <geometry>
        <mesh filename="package://spot/meshes/right_arm.dae"/>
      </geometry>
      <material name="blue"/>
    </visual>
    <collision>
      <geometry>
        <mesh filename="package://spot/meshes/right_arm.dae"/>
      </geometry>
      <origin rpy="0.0 0 0" xyz="0 -0.2 -0.57"/>
    </collision>
    <inertial>
      <mass value="0.7"/>
      <inertia ixx="1.0" ixy="0.0" ixz="0.0" iyy="1.0" iyz="0.0" izz="1.0"/>
    </inertial>
  </link>


  <joint name="right_front_arm_to_shoulder" type="revolute">
    <axis xyz="0 1 0"/>
    <limit effort="1000.0" lower="-0.610865" upper="1.48353" velocity="0.5"/>
    <origin rpy="0 0.610865 0" xyz="0 -0.2594 0.107"/>
    <parent link="right_front_joint"/>
    <child link="right_front_arm"/>
  </joint>

  <!--right back arm-->

  <link name="right_back_arm">
    <visual>
      <origin rpy="0.0 0 0" xyz="0 -0.2 -0.57"/>
      <geometry>
        <mesh filename="package://spot/meshes/right_arm.dae"/>
      </geometry>
      <material name="blue"/>
    </visual>
    <collision>
      <geometry>
        <mesh filename="package://spot/meshes/right_arm.dae"/>
      </geometry>
      <origin rpy="0.0 0 0" xyz="0 -0.2 -0.57"/>
    </collision>
    <inertial>
      <mass value="0.7"/>
      <inertia ixx="1.0" ixy="0.0" ixz="0.0" iyy="1.0" iyz="0.0" izz="1.0"/>
    </inertial>
  </link>


  <joint name="right_back_arm_to_shoulder" type="revolute">
    <axis xyz="0 1 0"/>
    <limit effort="1000.0" lower="-0.610865" upper="1.48353" velocity="0.5"/>
    <origin rpy="0 0.610865 0" xyz="0 -0.2594 0.107"/>
    <parent link="right_back_joint"/>
    <child link="right_back_arm"/>
  </joint>

  <!--left front foot-->

  <link name="left_front_foot">
    <visual>
      <origin rpy="0.0 0 0" xyz="0.602699 0.244238 0.017011"/>
      <geometry>
        <mesh filename="package://spot/meshes/left_foot.dae"/>
      </geometry>
      <material name="blue"/>
    </visual>
    <collision>
      <geometry>
        <mesh filename="package://spot/meshes/left_foot.dae"/>
      </geometry>
      <origin rpy="0.0 0 0" xyz="0.602699 0.244238 0.017011"/>
    </collision>
    <inertial>
      <mass value="0.7"/>
      <inertia ixx="1.0" ixy="0.0" ixz="0.0" iyy="1.0" iyz="0.0" izz="1.0"/>
    </inertial>
  </link>


  <joint name="left_front_foot_to_arm" type="revolute">
    <axis xyz="0 1 0"/>
    <limit effort="1000.0" lower="-0.959931" upper="1.5708" velocity="0.5"/>
    <origin rpy="0 0 0" xyz="0.11924 0 -1.1419"/>
    <parent link="left_front_arm"/>
    <child link="left_front_foot"/>
  </joint>

  <!--left back foot-->

  <link name="left_back_foot">
    <visual>
      <origin rpy="0.0 0 0" xyz="0.602699 0.244238 0.017011"/>
      <geometry>
        <mesh filename="package://spot/meshes/left_foot.dae"/>
      </geometry>
      <material name="blue"/>
    </visual>
    <collision>
      <geometry>
        <mesh filename="package://spot/meshes/left_foot.dae"/>
      </geometry>
      <origin rpy="0.0 0 0" xyz="0.602699 0.244238 0.017011"/>
    </collision>
    <inertial>
      <mass value="0.7"/>
      <inertia ixx="1.0" ixy="0.0" ixz="0.0" iyy="1.0" iyz="0.0" izz="1.0"/>
    </inertial>
  </link>


  <joint name="left_back_foot_to_arm" type="revolute">
    <axis xyz="0 1 0"/>
    <limit effort="1000.0" lower="-0.959931" upper="1.5708" velocity="0.5"/>
    <origin rpy="0 0 0" xyz="0.11924 0 -1.1419"/>
    <parent link="left_back_arm"/>
    <child link="left_back_foot"/>
  </joint>

  <!--right front foot-->

  <link name="right_front_foot">
    <visual>
      <origin rpy="0.0 0 0" xyz="0.602699 -0.244238 0.017011"/>
      <geometry>
        <mesh filename="package://spot/meshes/right_foot.dae"/>
      </geometry>
      <material name="blue"/>
    </visual>
    <collision>
      <geometry>
        <mesh filename="package://spot/meshes/right_foot.dae"/>
      </geometry>
      <origin rpy="0.0 0 0" xyz="0.602699 -0.244238 0.017011"/>
    </collision>
    <inertial>
      <mass value="0.7"/>
      <inertia ixx="1.0" ixy="0.0" ixz="0.0" iyy="1.0" iyz="0.0" izz="1.0"/>
    </inertial>
  </link>


  <joint name="right_front_foot_to_arm" type="revolute">
    <axis xyz="0 1 0"/>
    <limit effort="1000.0" lower="-0.959931" upper="1.5708" velocity="0.5"/>
    <origin rpy="0 0 0" xyz="0.11924 0 -1.1419"/>
    <parent link="right_front_arm"/>
    <child link="right_front_foot"/>
  </joint>

  <!--right back foot-->

  <link name="right_back_foot">
    <visual>
      <origin rpy="0.0 0 0" xyz="0.602699 -0.244238 0.017011"/>
      <geometry>
        <mesh filename="package://spot/meshes/right_foot.dae"/>
      </geometry>
      <material name="blue"/>
    </visual>
    <collision>
      <geometry>
        <mesh filename="package://spot/meshes/right_foot.dae"/>
      </geometry>
      <origin rpy="0.0 0 0" xyz="0.602699 -0.244238 0.017011"/>
    </collision>
    <inertial>
      <mass value="0.7"/>
      <inertia ixx="1.0" ixy="0.0" ixz="0.0" iyy="1.0" iyz="0.0" izz="1.0"/>
    </inertial>
  </link>


  <joint name="right_back_foot_to_arm" type="revolute">
    <axis xyz="0 1 0"/>
    <limit effort="1000.0" lower="-0.959931" upper="1.5708" velocity="0.5"/>
    <origin rpy="0 0 0" xyz="0.11924 0 -1.1419"/>
    <parent link="right_back_arm"/>
    <child link="right_back_foot"/>
  </joint>

  

</robot>
